<?xml version="1.0" ?>
<!-- =================================================================================== -->
<!-- |    This document was autogenerated by xacro from urdf/batmobile.urdf.xacro      | -->
<!-- |    EDITING THIS FILE BY HAND IS NOT RECOMMENDED                                 | -->
<!-- =================================================================================== -->
<robot name="batmobile">
  <material name="blue">
    <color rgba="0.0 0.0 0.8 1.0"/>
  </material>
  <material name="green">
    <color rgba="0.0 0.8 0.0 1.0"/>
  </material>
  <material name="red">
    <color rgba="0.8 0.0 0.0 1.0"/>
  </material>
  <!--material -->
  <gazebo>
    <plugin filename="libgazebo_ros_diff_drive.so" name="differential_drive_controller">
      <leftJoint>left_wheel_joint</leftJoint>
      <rightJoint>right_wheel_joint</rightJoint>
      <wheelSeparation>0.21</wheelSeparation>
      <wheelDiameter>0.2</wheelDiameter>
      <wheelAcceleration>10.0</wheelAcceleration>
      <robotBaseFrame>root_link</robotBaseFrame>
      <publishWheelTF>true</publishWheelTF>
    </plugin>
  </gazebo>
  <gazebo>
    <plugin filename="libgazebo_ros_imu.so" name="imu_plugin">
      <alwaysOn>true</alwaysOn>
      <bodyName>imu_link</bodyName>
      <topicName>imu</topicName>
      <serviceName>imu_service</serviceName>
      <gaussianNoise>0.0</gaussianNoise>
      <updateRate>20.0</updateRate>
    </plugin>
  </gazebo>
  <link name="base_link"/>
  <link name="root_link">
    <visual>
      <origin rpy="0. -0.15 0.0" xyz="0.0 0.0 0.02"/>
      <geometry>
        <mesh filename="package://batmobile/meshes/chassis.dae" scale="0.9 0.5 0.5"/>
      </geometry>
    </visual>
    <collision>
      <origin rpy="0. -0.15 0.0" xyz="0.0 0.0 0.02"/>
      <geometry>
        <box size=".41 .16 .1"/>
      </geometry>
    </collision>
    <inertial>
      <origin rpy="0. -0.05 0.0"/>
      <mass value="10"/>
      <inertia ixx="0.02966666666666667" ixy="0.0" ixz="0.0" iyy="0.14841666666666664" iyz="0.0" izz="0.16141666666666662"/>
    </inertial>
  </link>
  <link name="left_wheel_link">
    <collision>
      <geometry>
        <cylinder length="0.05" radius="0.1"/>
      </geometry>
    </collision>
    <visual>
      <geometry>
        <cylinder length="0.05" radius="0.1"/>
      </geometry>
      <material name="blue"/>
    </visual>
    <inertial>
      <origin rpy="0 0 0"/>
      <mass value="2.5"/>
      <inertia ixx="0.006770833333333334" ixy="0.0" ixz="0.0" iyy="0.006770833333333334" iyz="0.0" izz="0.012500000000000002"/>
    </inertial>
  </link>
  <gazebo reference="left_wheel_link">
    <material>Gazebo/Blue</material>
  </gazebo>
  <joint name="left_wheel_joint" type="continuous">
    <parent link="root_link"/>
    <child link="left_wheel_link"/>
    <axis xyz="0 0 1"/>
    <origin rpy="-1.5707963267948966 0 0" xyz="-0.05 0.125 0"/>
  </joint>
  <link name="right_wheel_link">
    <collision>
      <geometry>
        <cylinder length="0.05" radius="0.1"/>
      </geometry>
    </collision>
    <visual>
      <geometry>
        <cylinder length="0.05" radius="0.1"/>
      </geometry>
      <material name="blue"/>
    </visual>
    <inertial>
      <origin rpy="0 0 0"/>
      <mass value="2.5"/>
      <inertia ixx="0.006770833333333334" ixy="0.0" ixz="0.0" iyy="0.006770833333333334" iyz="0.0" izz="0.012500000000000002"/>
    </inertial>
  </link>
  <gazebo reference="right_wheel_link">
    <material>Gazebo/Blue</material>
  </gazebo>
  <joint name="right_wheel_joint" type="continuous">
    <parent link="root_link"/>
    <child link="right_wheel_link"/>
    <axis xyz="0 0 -1"/>
    <origin rpy="1.5707963267948966 0 0" xyz="-0.05 -0.125 0"/>
  </joint>
  <link name="caster_wheel_link">
    <collision>
      <geometry>
        <sphere radius="0.06"/>
      </geometry>
    </collision>
    <visual>
      <geometry>
        <sphere radius="0.06"/>
      </geometry>
      <material name="red"/>
    </visual>
    <inertial>
      <origin rpy="0 0 0"/>
      <mass value="0.1"/>
      <inertia ixx="0.000144" ixy="0.0" ixz="0.0" iyy="0.000144" iyz="0.0" izz="0.000144"/>
    </inertial>
  </link>
  <link name="caster_wheel_holder">
    <collision>
      <geometry>
        <cylinder length="0.01" radius="0.001"/>
      </geometry>
    </collision>
    <visual>
      <geometry>
        <cylinder length="0.01" radius="0.001"/>
      </geometry>
      <material name="green"/>
    </visual>
  </link>
  <gazebo reference="caster_wheel_link">
    <material>Gazebo/Blue</material>
  </gazebo>
  <joint name="base_joint" type="fixed">
    <parent link="base_link"/>
    <child link="root_link"/>
    <axis xyz="0 0 0"/>
    <origin rpy="0 0 0" xyz="0 0 .1"/>
  </joint>
  <joint name="caster_wheel_holder_joint" type="continuous">
    <parent link="root_link"/>
    <child link="caster_wheel_holder"/>
    <axis xyz="0 0 1"/>
    <origin rpy="0 0 0" xyz="0.17 0.0 -0.03"/>
  </joint>
  <joint name="caster_wheel_joint" type="continuous">
    <parent link="root_link"/>
    <child link="caster_wheel_link"/>
    <axis xyz="0 1 0"/>
    <origin rpy="0 0 0" xyz="0.17 0.0 -0.03"/>
  </joint>
  <link name="imu_link">
    <collision>
      <geometry>
        <box size="0.03 0.03 0.03"/>
        <origin xyz="0 0 0.05977525298943969"/>
      </geometry>
    </collision>
    <visual>
      <geometry>
        <box size="0.03 0.03 0.03"/>
        <origin xyz="0 0 0.05977525298943969"/>
      </geometry>
      <material name="green"/>
    </visual>
  </link>
  <joint name="imu_joint" type="fixed">
    <parent link="root_link"/>
    <child link="imu_link"/>
    <axis xyz="0 0 0"/>
    <origin rpy="0 0 0" xyz=".205 0 .055"/>
  </joint>
</robot>

